<?xml version="1.0"?>
<robot xmlns:xacro="http://www.ros.org/wiki/xacro" >

    <xacro:include filename="inertial_macros.xacro"/>

    <material name="white">
        <color rgba="1 1 1 1" />
    </material>

    <material name="orange">
        <color rgba="1 0.3 0.1 1"/>
    </material>

    <material name="blue">
        <color rgba="0.2 0.2 1 1"/>
    </material>

    <material name="yellow">
        <color rgba="0.255 0.128 0.128 1"/>
    </material>

    <material name="black">
        <color rgba="0 0 0 1"/>
    </material>

    <!-- BASE LINK -->

    <link name="base_link">

    </link>

    <!-- CHASSIS LINK -->

    <joint name="chassis_joint" type="fixed">
        <parent link="base_link"/>
        <child link="chassis"/>
        <origin xyz="-0.158 0 0"/>
    </joint>

    <link name="chassis">
        <visual>
            <origin xyz="0.183 0 -0.02" rpy="0 0 ${pi}"/>
            <geometry>
                <mesh filename="file://$(find albot-description)/description/meshes/chassis_equiped.stl"/>
            </geometry>
            <material name="white"/>
        </visual>
        <collision>
            <origin  xyz="0.183 0 -0.02" rpy="0 0 ${pi}"/>
            <geometry>
                <mesh filename="file://$(find albot-description)/description/meshes/chassis_equiped.stl"/>
            </geometry>
        </collision>
        <xacro:inertial_box mass="5" x="0.455" y="0.4" z="0.263"> <!-- mass in kg, length and radius in meters (To Be Measured) -->
            <origin xyz="0.183 0 -.1" rpy="0 0 ${pi}"/>
        </xacro:inertial_box>
    </link>
    
    <!-- LEFT WHEEL LINK -->

    <joint name="left_wheel_joint" type="continuous">
        <parent link="base_link"/>
        <child link="left_wheel"/>
        <origin xyz="0 0.205 0" rpy="-${pi/2} 0 0" />
        <axis xyz="0 0 1"/>
    </joint>

    <link name="left_wheel">
        <visual>
            <geometry>
                <mesh filename="file://$(find albot-description)/description/meshes/standard_hover_wheels.stl"/>
            </geometry>
            <origin rpy="0 -1.57 0" />
        </visual>
        <collision>
            <origin rpy="0 -1.57 0" />
            <material name="black"/>
            <geometry>
                <mesh filename="file://$(find albot-description)/description/meshes/standard_hover_wheels.stl"/>
            </geometry>
        </collision>
        <xacro:inertial_cylinder mass="2.5" length="0.07" radius="0.105"> <!-- mass in kg, length and radius in meters (To Be Measured) -->
            <origin xyz="0 0 0" rpy="0 0 0"/>
        </xacro:inertial_cylinder>
    </link>

    <!-- RIGHT WHEEL LINK -->

    <joint name="right_wheel_joint" type="continuous">
        <parent link="base_link"/>
        <child link="right_wheel"/>
        <origin xyz="0 -0.205 0" rpy="${pi/2} 0 0" />
        <axis xyz="0 0 -1"/>
    </joint>

    <link name="right_wheel">
        <visual>
            <geometry>
                <mesh filename="file://$(find albot-description)/description/meshes/standard_hover_wheels.stl"/>
            </geometry>
            <origin rpy="0 -1.57 0" />
        </visual>
        <collision>
            <origin rpy="0 -1.57 0" />
            <material name="black"/>
            <geometry>
                <mesh filename="file://$(find albot-description)/description/meshes/standard_hover_wheels.stl"/>
            </geometry>
        </collision>
        <xacro:inertial_cylinder mass="2.5" length="0.07" radius="0.105"> <!-- mass in kg, length and radius in meters (To Be Measured) -->
            <origin xyz="0 0 0" rpy="0 0 0"/>
        </xacro:inertial_cylinder>
    </link>

    <!-- CASTER WHEEL LINK -->


    <joint name="caster_wheel_joint" type="fixed">
        <origin xyz="0.35 0 0"/>
        <parent link="chassis"/>
        <child link="caster_wheel"/>
    </joint>

    <link name="caster_wheel">
        <visual>
            <geometry>
                <mesh filename="file://$(find albot-description)/description/meshes/caster_wheel.stl"/>
            </geometry>
            <origin xyz="0.035 0 -0.10"/>
        </visual>
        <collision>
            <origin xyz="0.035 0 -0.10"/>
            <geometry>
                <mesh filename="file://$(find albot-description)/description/meshes/caster_wheel.stl"/>
            </geometry>
        </collision>
        <xacro:inertial_sphere mass="5" radius="0.05"> <!-- mass in kg, length and radius in meters (To Be Measured) -->
            <origin xyz="0 0 0" rpy="0 0 0"/>
        </xacro:inertial_sphere>
    </link>

    <gazebo reference="caster_wheel">
        <mu1 value="0.001"/> <!-- (To Be Measured) -->
        <mu2 value="0.001"/> <!-- (To Be Measured) -->
    </gazebo>

       
    
</robot>